<?xml version="1.0" ?>
<!-- =================================================================================== -->
<!-- |    This document was autogenerated by xacro from src/bcr_arm_description/urdf/bcr_arm.urdf.xacro | -->
<!-- |    EDITING THIS FILE BY HAND IS NOT RECOMMENDED                                 | -->
<!-- =================================================================================== -->
<robot name="bcr_arm">
  <!-- ========================= -->
  <!-- ros2_control 硬件接口定义 -->
  <!-- ========================= -->
  <material name="black">
    <color rgba="0.05 0.05 0.05 1.0"/>
  </material>
  <material name="gray">
    <color rgba="0.5 0.5 0.5 1.0"/>
  </material>
  <material name="blue">
    <color rgba="0.1 0.25 0.9 1.0"/>
  </material>
  <material name="orange">
    <color rgba="1.0 0.5 0.1 1.0"/>
  </material>
  <!-- ========================= -->
  <!-- Inertial helper 惯性参数-->
  <!-- ========================= -->
  <!-- ========================= -->
  <!-- Base link -->
  <!-- ========================= -->
  <link name="base_link">
    <visual>
      <origin rpy="0 0 0" xyz="0 0 0.05"/>
      <geometry>
        <cylinder length="0.10" radius="0.18"/>
      </geometry>
      <material name="black"/>
    </visual>
    <collision>
      <origin rpy="0 0 0" xyz="0 0 0.05"/>
      <geometry>
        
        <cylinder length="0.10" radius="0.18"/>
      </geometry>
    </collision>
    <inertial>
      <origin rpy="0 0 0" xyz="0 0 0"/>
      <mass value="5.0"/>
      <inertia ixx="0.04466666666666667" ixy="0.0" ixz="0.0" iyy="0.04466666666666667" iyz="0.0" izz="0.08099999999999999"/>
    </inertial>
  </link>
  <link name="link1">
    <visual>
      <origin rpy="0 0 0" xyz="0 0 0.15"/>
      <geometry>
        <cylinder length="0.3" radius="0.055"/>
      </geometry>
      <material name="gray"/>
    </visual>
    <collision>
      <origin rpy="0 0 0" xyz="0 0 0.15"/>
      <geometry>
        <cylinder length="0.3" radius="0.055"/>
      </geometry>
    </collision>
    <inertial>
      <origin rpy="0 0 0" xyz="0 0 0"/>
      <mass value="1.5"/>
      <inertia ixx="0.012384374999999998" ixy="0.0" ixz="0.0" iyy="0.012384374999999998" iyz="0.0" izz="0.00226875"/>
    </inertial>
  </link>
  <link name="link2">
    <visual>
      <origin rpy="0 0 0" xyz="0 0 0.175"/>
      <geometry>
        <cylinder length="0.35" radius="0.05"/>
      </geometry>
      <material name="blue"/>
    </visual>
    <collision>
      <origin rpy="0 0 0" xyz="0 0 0.175"/>
      <geometry>
        <cylinder length="0.35" radius="0.05"/>
      </geometry>
    </collision>
    <inertial>
      <origin rpy="0 0 0" xyz="0 0 0"/>
      <mass value="1.3"/>
      <inertia ixx="0.014083333333333331" ixy="0.0" ixz="0.0" iyy="0.014083333333333331" iyz="0.0" izz="0.0016250000000000001"/>
    </inertial>
  </link>
  <link name="link3">
    <visual>
      <origin rpy="0 0 0" xyz="0 0 0.15"/>
      <geometry>
        <cylinder length="0.3" radius="0.045"/>
      </geometry>
      <material name="gray"/>
    </visual>
    <collision>
      <origin rpy="0 0 0" xyz="0 0 0.15"/>
      <geometry>
        <cylinder length="0.3" radius="0.045"/>
      </geometry>
    </collision>
    <inertial>
      <origin rpy="0 0 0" xyz="0 0 0"/>
      <mass value="1.1"/>
      <inertia ixx="0.008806875" ixy="0.0" ixz="0.0" iyy="0.008806875" iyz="0.0" izz="0.00111375"/>
    </inertial>
  </link>
  <link name="link4">
    <visual>
      <origin rpy="0 0 0" xyz="0 0 0.125"/>
      <geometry>
        <cylinder length="0.25" radius="0.04"/>
      </geometry>
      <material name="blue"/>
    </visual>
    <collision>
      <origin rpy="0 0 0" xyz="0 0 0.125"/>
      <geometry>
        <cylinder length="0.25" radius="0.04"/>
      </geometry>
    </collision>
    <inertial>
      <origin rpy="0 0 0" xyz="0 0 0"/>
      <mass value="0.9"/>
      <inertia ixx="0.0050475" ixy="0.0" ixz="0.0" iyy="0.0050475" iyz="0.0" izz="0.00072"/>
    </inertial>
  </link>
  <link name="link5">
    <visual>
      <origin rpy="0 0 0" xyz="0 0 0.1"/>
      <geometry>
        <cylinder length="0.2" radius="0.035"/>
      </geometry>
      <material name="gray"/>
    </visual>
    <collision>
      <origin rpy="0 0 0" xyz="0 0 0.1"/>
      <geometry>
        <cylinder length="0.2" radius="0.035"/>
      </geometry>
    </collision>
    <inertial>
      <origin rpy="0 0 0" xyz="0 0 0"/>
      <mass value="0.7"/>
      <inertia ixx="0.0025477083333333337" ixy="0.0" ixz="0.0" iyy="0.0025477083333333337" iyz="0.0" izz="0.00042875000000000004"/>
    </inertial>
  </link>
  <link name="link6">
    <visual>
      <origin rpy="0 0 0" xyz="0 0 0.08"/>
      <geometry>
        <cylinder length="0.16" radius="0.03"/>
      </geometry>
      <material name="blue"/>
    </visual>
    <collision>
      <origin rpy="0 0 0" xyz="0 0 0.08"/>
      <geometry>
        <cylinder length="0.16" radius="0.03"/>
      </geometry>
    </collision>
    <inertial>
      <origin rpy="0 0 0" xyz="0 0 0"/>
      <mass value="0.5"/>
      <inertia ixx="0.0011791666666666667" ixy="0.0" ixz="0.0" iyy="0.0011791666666666667" iyz="0.0" izz="0.000225"/>
    </inertial>
  </link>
  <link name="link7">
    <visual>
      <origin rpy="0 0 0" xyz="0 0 0.06"/>
      <geometry>
        <cylinder length="0.12" radius="0.025"/>
      </geometry>
      <material name="orange"/>
    </visual>
    <collision>
      <origin rpy="0 0 0" xyz="0 0 0.06"/>
      <geometry>
        <cylinder length="0.12" radius="0.025"/>
      </geometry>
    </collision>
    <inertial>
      <origin rpy="0 0 0" xyz="0 0 0"/>
      <mass value="0.4"/>
      <inertia ixx="0.0005425000000000001" ixy="0.0" ixz="0.0" iyy="0.0005425000000000001" iyz="0.0" izz="0.00012500000000000003"/>
    </inertial>
  </link>
  <!-- Tool frame -->
  <link name="tool0">
    <visual>
      <origin rpy="0 0 0" xyz="0 0 0.04"/>
      <geometry>
        <box size="0.08 0.04 0.08"/>
      </geometry>
      <material name="orange"/>
    </visual>
    <collision>
      <origin rpy="0 0 0" xyz="0 0 0.04"/>
      <geometry>
        <box size="0.08 0.04 0.08"/>
      </geometry>
    </collision>
    <inertial>
      <origin rpy="0 0 0" xyz="0 0 0"/>
      <mass value="0.3"/>
      <!-- 转动惯性 -->
      <!-- 这里需要六个参数来描述物体的转动惯性，是一个3×3的对称矩阵 -->
      <!-- ixx  ixy  ixz
           ixy  iyy  iyz
           ixz  iyz  izz -->
      <!--ixx是绕x轴的运动  -->
      <!-- ixy=0 旋转是正的，绕x轴旋转不会歪的y轴上 -->
      <inertia ixx="0.00019999999999999998" ixy="0.0" ixz="0.0" iyy="0.00032" iyz="0.0" izz="0.00019999999999999998"/>
    </inertial>
  </link>
  <!-- ========================= -->
  <!-- 7-DOF joints -->
  <!-- ========================= -->
  <!-- joint1: base yaw -->
  <joint name="joint1" type="revolute">
    <parent link="base_link"/>
    <child link="link1"/>
    <origin rpy="0 0 0" xyz="0 0 0.10"/>
    <axis xyz="0 0 1"/>
    <limit effort="100.0" lower="-3.1416" upper="3.1416" velocity="1.5"/>
  </joint>
  <!-- joint2: shoulder pitch -->
  <joint name="joint2" type="revolute">
    <parent link="link1"/>
    <child link="link2"/>
    <origin rpy="0 0 0" xyz="0 0 0.30"/>
    <axis xyz="0 1 0"/>
    <limit effort="100.0" lower="-2.2" upper="2.2" velocity="1.5"/>
  </joint>
  <!-- joint3: elbow pitch -->
  <joint name="joint3" type="revolute">
    <parent link="link2"/>
    <child link="link3"/>
    <origin rpy="0 0 0" xyz="0 0 0.35"/>
    <axis xyz="0 1 0"/>
    <limit effort="100.0" lower="-2.2" upper="2.2" velocity="1.5"/>
  </joint>
  <!-- joint4: wrist roll -->
  <joint name="joint4" type="revolute">
    <parent link="link3"/>
    <child link="link4"/>
    <origin rpy="0 0 0" xyz="0 0 0.30"/>
    <axis xyz="1 0 0"/>
    <limit effort="80.0" lower="-3.1416" upper="3.1416" velocity="1.5"/>
  </joint>
  <!-- joint5: wrist pitch -->
  <joint name="joint5" type="revolute">
    <parent link="link4"/>
    <child link="link5"/>
    <origin rpy="0 0 0" xyz="0 0 0.25"/>
    <axis xyz="0 1 0"/>
    <limit effort="80.0" lower="-2.2" upper="2.2" velocity="1.5"/>
  </joint>
  <!-- joint6: wrist roll -->
  <joint name="joint6" type="revolute">
    <parent link="link5"/>
    <child link="link6"/>
    <origin rpy="0 0 0" xyz="0 0 0.20"/>
    <axis xyz="1 0 0"/>
    <limit effort="60.0" lower="-3.1416" upper="3.1416" velocity="1.5"/>
  </joint>
  <!-- joint7: final pitch -->
  <joint name="joint7" type="revolute">
    <parent link="link6"/>
    <child link="link7"/>
    <origin rpy="0 0 0" xyz="0 0 0.16"/>
    <axis xyz="0 1 0"/>
    <limit effort="60.0" lower="-2.2" upper="2.2" velocity="1.5"/>
  </joint>
  <!-- fixed tool joint -->
  <joint name="tool_joint" type="fixed">
    <parent link="link7"/>
    <child link="tool0"/>
    <origin rpy="0 0 0" xyz="0 0 0.12"/>
  </joint>
  <ros2_control name="bcr_arm_system" type="system">
    <hardware>
      <!-- 这个插件让 ros2_control 
         能和 Ignition Gazebo 仿真器通信，读取/发送关节数据。 -->
      <plugin>ign_ros2_control/IgnitionSystem</plugin>
    </hardware>
    <joint name="joint1">
      <command_interface name="position"/>
      <state_interface name="position"/>
      <state_interface name="velocity"/>
    </joint>
    <joint name="joint2">
      <command_interface name="position"/>
      <state_interface name="position"/>
      <state_interface name="velocity"/>
    </joint>
    <joint name="joint3">
      <command_interface name="position"/>
      <state_interface name="position"/>
      <state_interface name="velocity"/>
    </joint>
    <joint name="joint4">
      <command_interface name="position"/>
      <state_interface name="position"/>
      <state_interface name="velocity"/>
    </joint>
    <joint name="joint5">
      <command_interface name="position"/>
      <state_interface name="position"/>
      <state_interface name="velocity"/>
    </joint>
    <joint name="joint6">
      <command_interface name="position"/>
      <state_interface name="position"/>
      <state_interface name="velocity"/>
    </joint>
    <joint name="joint7">
      <command_interface name="position"/>
      <state_interface name="position"/>
      <state_interface name="velocity"/>
    </joint>
  </ros2_control>
  <!-- Gazebo 插件，加载控制器 YAML 配置 -->
  <gazebo>
    <plugin filename="ign_ros2_control-system" name="ign_ros2_control::IgnitionROS2ControlPlugin">
      <parameters>/home/bbbkkk/my_brc_arm_ws/install/bcr_arm_gazebo/share/bcr_arm_gazebo/config/ros2_controllers.yaml</parameters>
    </plugin>
  </gazebo>
</robot>
